Workbook

Sheet CX進捗0403
A1: # | B1: 課題 （現状と影響） | C1: 重要 度 | D1: 緊急 度 | E1: PJキーワード | F1: PJ内容 （施策の要点） | G1: 期間・期限 （マイルストーン） | H1: 関係部門 | I1: CX担当 | J1: 当週 進捗記入 | K1: ステータス | L1: 進捗 「計画に対してどこまで進んでいるか」 | M1: 課題・リスク 「問題は何か、将来の危険は何か」 | N1: 対応方針・アクション 「どう解決するか、次に何をやるか」 | O1: 意思決定事項 「経営・上位者に判断してほしいこと」 | P1: KPI・成果 「どれだけ価値が出ているか」
A2: =ROW()-1 -> 1 | B2: 欠品低減に向けての取り組み | C2: 高 | D2: 中 | E2: 信頼の棚 自動発注 | F2: ・入替リスト実施精度向上 ・最低在庫１→２ ・欠品調査PG、現状把握・分析・対応 バイヤー軸、店舗運営部軸 | G2: ・2/1全店欠品調査 開始 ・3/1商品部、店舗運営部用分析画面リリース ・欠品チェックメンションRPA | H2: CX推進部 商品部 店舗運営部 | I2: 齋藤 足立 | J2: 齋藤 | K2: 進行中 | M2: 調査漏れがある 欠品数が減っていない 欠品数が少ないと思われる店舗がある | N2: ・詳細を坪井泰樹さんからヒアリング 3/31_欠品対策運用の徹底 ・3月末 欠品チェックリマインドRPA作成 経営戦略本部：現地確認
A3: =ROW()-1 -> 2 | B3: グループウェア導入 | C3: 高 | D3: 高 | E3: グループウェア | F3: デスクネッツネオ、サイバーメールの導入 | G3: ・サイバーメイル運用開始：物販4/6（月）、調剤4/4（土） ・杏林堂MSドメイン終了：2027.02.28 | H3: 全社 | I3: 横井 足立 | J3: 横井 | K3: 進行中 | M3: ①名刺の差し替え→6万枚\63,360 ・HD所属を除く：298,320円（税抜）＝約30万 ・HD所属を含む：397,440円（税抜）＝約40万 ★原稿作成２W、印刷２営業日 ②役員以上の方のCybermailの周知 ③メールフォルダ容量の拡張の必要性 ・50G拡張：毎月約25万円 ④4/1移動者のアドレス申請→間に合いません ⑤outlookメール終了 店舗：2026/07終了 本部員：2027/02/28終了 ⑥outlookスケジュール連携 ⑦事故報告書：THDよりデスクネッツネオを利用に運用変更 ・添付容量確認 社長グループの選定 事故報告書メンションの設定 メールアカウント管理→情報システム | N3: 事前準備 outlookのグループアドレス帳整備 →情報システム部へ依頼 新ネットフォルダの展開 →本部員各自でインストール依頼予定 メールフォルダの準備 アカウント申請整理
A4: =ROW()-1 -> 3 | B4: 商品部、店舗運営部 業務可視化、生産性向上 | C4: 高 | D4: 高 | E4: Qasee分析 | F4: PCの操作ログ（アプリ使用時間、キー入力量など）を自動収集アプリを導入 | H4: 商品部 店舗運営部 | I4: 鈴木孝 | J4: 鈴木孝 | K4: 進行中 | L4: 4/16 商品部振り返り待ち | M4: 自動で振り分けられない作業を「仕分け」する必要があるが、やり切れていない。 運用初期なので、運用が上手く乗るまで少し細かくチェック。 | N4: 商品部の業務分析 ・鈴木雅彦・小峰・疋田・大庭・栗田・中野
A5: =ROW()-1 -> 4 | B5: 契約書レビューAIクラウド | C5: 中 | D5: 低 | E5: リセ LeCHECK | F5: 契約書レビューAIクラウドの導入検討 ・レビューの効率化 ・契約リスクの早期発見 トラブル防止、コンプライアンス強化 ・法務ナレッジの標準化 担当者依存から脱却 すすかけリーガルチェック 2026年3月まで 21件、2025年 80件、2024年 131件、2023年 105件 すずかけ顧問料：月2.7万円 | G5: ・3/19導入済 ・4月末まで：法務リサーチ機能β版追加 | H5: 総務 | I5: 鈴木孝 齋藤 | J5: 齋藤 | K5: 進行中 | M5: 開発部、お客様相談室にて把握できていないリーガルチェックあり 新しい法律（取適法）などに対しても弁護士30人でチェック | N5: リセ社より操作説明予定（予定調整中） 法務リサーチ機能β版追加、総務に機能リリースのつなぎまでCXで行う
A6: =ROW()-1 -> 5 | B6: 議事録自動化AIエージェント導入 | C6: 高 | D6: 高 | E6: JAPAN AI | F6: 生成AI活用 ・２か月試験運用で継続判断 ・AIエージェント内製開発も視野 | H6: CX推進部 | I6: 横井 鈴木孝 足立 | J6: 鈴木孝 | K6: 進行中 | L6: トライアル契約完了 4/7説明会 | M6: リーガルチェックにて漏れ発生 ・プロバイダー側が勝手に利用規約変更、サービス終了 ・損害賠償責任の上限がない | N6: 3/23 JAPAN AI契約
A7: =ROW()-1 -> 6 | B7: 資料作成AIエージェント導入 | C7: 高 | D7: 高 | E7: JAPAN AI | F7: 生成AI活用 | H7: CX推進部 | I7: 横井 鈴木孝 足立 | J7: 鈴木孝 | K7: 進行中 | L7: NotobookLM導入完了8アカウント | M7: JAPAN AI導入 NotebookLM（GWS導入） | N7: 3/23 JAPAN AI契約
A8: =ROW()-1 -> 7 | B8: 価格ロジックと販促見直し | C8: 高 | D8: 中 | E8: 単品売価上下影響 価格弾力性 | F8: 値付け適正化と会社影響、販促重複の把握 割引率による弾力性調査 | H8: 営業推進部 CX推進部 | I8: 石川 | K8: 進行中 | M8: DB構築とAIエージェント活用の検討 | N8: CODIQ分析、方向性検討 3/18
A9: =ROW()-1 -> 8 | B9: ツルハAIチャットボット導入 | C9: 中 | D9: 中 | E9: Knowledge Forest TeachMeBiz廃止 RAG MCP | F9: THD、NECで作成したAIチャットボット 杏林堂には改修可能な開発スペース マニュアル精査等はTHD業務改革Gが指導 Claude Codeライセンス追加 | G9: ・ツルハ：2026年5月リリース予定 ・杏林堂：2026年9月リリース目標 | H9: CX推進部 店舗運営部 THD経営企画部 | I9: 足立 鈴木孝 | K9: 進行中 | M9: チャットボット応答精度、対応範囲決め 調剤部適応、労務smartHRとのすみわけ TeachMeBiz廃止→マニュアル格納場所検討 マニュアル/QA対応しやすいAIエージェントの模索（VINX） | N9: マニュアル精査 標準的なチャットボットのアーキテクト確認 JAPAN AIとの比較
A10: =ROW()-1 -> 9 | B10: 店舗出店予測の向上 | C10: 高 | D10: 低 | E10: 店舗出店予測 SalesSencer | F10: ウエルシアTruedata社SalesSencerの導入 IC約3000万円、RC約3500万円 AIエージェント作成（CODIQ） | H10: 店舗開発本部 経営戦略本部 | I10: 石川 足立 | K10: 未着手 | M10: 予測精度向上5%まで （現状：25%～40%、SalesSencer：10%） | N10: ツルハHD取締役会決議事項（ツルハHD開発本部長 遠山取締役 上申予定） CODIQにて過去データより別途活用方法検討
A11: =ROW()-1 -> 10 | B11: 勤務割、ワークフロー | C11: 中 | D11: 中 | E11: ワークフロー | F11: EXCELマクロによる ・ワークフロー作成の効率化 ×R-Shift | H11: 物販 調剤 ネットスーパー | I11: 横井 鈴木孝 | K11: 進行中 | M11: ・ワークスケジュールAIエージェントまたはアプリの導入 ・感情加味したシフト作成 調剤：調整機能必要 | N11: ・CODIQ相談中 ・ワークフローアプリ調査中
A12: =ROW()-1 -> 11 | B12: 店舗応援依頼作業の最適化、省人化 | C12: 中 | D12: 中 | E12: 応援マッチング | F12: EXCELマクロによる ・店舗応援の効率化 | H12: 物販 調剤 ネットスーパー | I12: 横井 鈴木孝 | J12: 鈴木孝 | K12: 進行中 | L12: 調剤部は5月より順次に運用を開始予定 | M12: ・応援計算ツール EXCELマクロ調剤調整中 →調剤：15日までシフト作成、16日ツール使用の運用 →物販：運用可能か確認中 | N12: ・応援マッチング マクロ改修、運用調整 ・CODIQ相談中
A13: =ROW()-1 -> 12 | B13: 経理月次締め処理の清流化 | C13: 高 | D13: 高 | E13: 経理締め処理 | F13: 属人化作業を廃止して清流化する 2026年5月まで | H13: 経理 情報システム CX推進部 | I13: 石川 | J13: 石川 | K13: 進行中 | M13: ・属人化業務（高山さんPG）の共通化 | N13: ・経理Martsolution業務落とし込み ・高山さんPG対応
A14: =ROW()-1 -> 13 | B14: 店舗連絡のルールメイキング | C14: 高 | D14: 高 | E14: 連絡ルール統一PJ | F14: メール件名のルール作成 わかりやすい件名にして店舗連絡精度を向上 | H14: 全社 | I14: 横井 鈴木孝 | J14: 横井 | K14: 進行中 | M14: mailto環境依存度の確認 労務：「通達」と「辞令（社報）」 | N14: ・各部意見集約 4/14：打ち合わせ
A15: =ROW()-1 -> 14 | B15: AI棚割導入 | C15: 中 | D15: 低 | E15: Tanagram Sotoremaneger プリファードNW | F15: エンド、プロモの棚割り（全店約1万本）作成 ストマネAIの検討 写真から棚割り作成（店舗入替後の入力軽減） | H15: 商品部 | I15: 横井 | J15: 横井 | K15: 未着手 | M15: 作成精度 運用方法（都度CSVファイルを手動で取込しなければならない） | N15: ・花王AI棚割り確認 →川島さんへ ・プリファードNWの紹介 →商品部、店舗運営部
A16: =ROW()-1 -> 15 | B16: KOGORO改修 | C16: 高 | D16: 高 | E16: KOGORO | F16: ・商品部、営業推進部のレポートを帳票にする ・日次予算作成ロジック改修 ・カテゴリー変更後実績反映ロジック ・正味売上粗利 | H16: CX推進部 商品部 店舗運営部 経営企画部 | I16: 石川 | K16: 進行中 | M16: 神戸DCへのサーバー移行スケジュール未確定（発注から3か月） 開発サーバー容量不足 D:200G残/800G 外付けSSD追加（2t） | N16: 次回要件定義 3月下旬帳票レイアウト改修一部リリース 日別予算ロジック設計 ETL設計3月末まで→開発 ジョブスケジューリング
A17: =ROW()-1 -> 16 | B17: コロンボ、かみさんの更新改修 | C17: 中 | D17: 中 | E17: コロンボ | F17: ・かみさんの更新改修 | H17: CX推進部 | I17: 石川 | K17: 着手 | M17: KOGOROと重複 かみさんの利用シーンを整理 | N17: 仕様確認中
A18: =ROW()-1 -> 17 | B18: 内製アプリ | C18: 中 | D18: 中 | E18: 買取DC 欠品調査PG | F18: アプリ使用のDB管理（MySQL） | H18: CX推進部 | I18: 足立 石川 | K18: 未着手 | M18: 神戸DCへのサーバー移行：RedHatがない
A19: =ROW()-1 -> 18 | B19: VoC収集 | C19: 高 | D19: 中 | E19: お客様の声 | F19: VoC収集→分類→改善のサイクル設計、顧客体験指標の運用 まじかまじボイス ・クレーム ・商品要望 ・本社宛クレーム→THD報告 イオングループ：SalesForece 博報堂 アソボーノ 生成AI活用サービス | H19: CX推進部 業務推進部 お客様相談室 | I19: 鈴木孝 石川 齋藤 鈴木佑 | J19: 石川 | K19: 進行中 | M19: お客様の声 ・お客様相談室 HP ・ポイント管理事務局 ・店舗紙→AIーOCR ・QRコード アンケートフォーム ・掲示方法 店舗の返信内容の改善（お客様相談室） ・商品仕入れの依頼時に他の商品をお勧めしない ・過去の返信内容がわからない→Gemini活用 履歴管理が不徹底 | N19: 静岡支社で検証 キックオフ調整中 お客様の声の返信フロー
A20: =ROW()-1 -> 19 | B20: RPA統合、スリム化して対応範囲を広げる | C20: 高 | D20: 高 | E20: RPA | F20: ・営業推進タスク精査 ・日次生産性Power BI ・労務RPA コスト：169,400円／月 | H20: 全社 | I20: 足立 石川 | K20: 進行中 | M20: 個人向けタスクの精査
A21: =ROW()-1 -> 20 | B21: コミュニケーション基盤 | C21: 中 | D21: 中 | E21: MSライセンス | F21: 1. 組織の情報共有のリアルタイム化（属人化を防ぎ、組織の情報資産を可視化） 2. 部門・拠点を超えたコラボレーション促進（サイロ化結合、スピードを向上） 3. 業務プロセスのデジタル化（業務プロセスデジタル化、生産性を向上） 4. ナレッジマネジメントの実現（組織知の蓄積） 5. DX施策の展開プラットフォーム（DXを拡張する基盤、社内チャットボット） 6. 働き方改革・リモートワーク対応（柔軟な働き方と人材確保） | G21: MSリセラー変更タイミング ・杏林堂ドメイン終了：2027/02/28 ・ツルハドメイン開始：2027/03/01 | H21: 全社 | I21: 鈴木孝 横井 | J21: 鈴木孝 横井 | K21: 未着手 | M21: 固有のアドレスは別メールサーバーで立ち上げ可能か検討 | N21: 杏林堂コスト算出（MSから見積提出）
A22: =ROW()-1 -> 21 | B22: 電子棚札導入 | C22: 高 | D22: 低 | E22: 電子棚札 | F22: 株ツルハ（本郷店、北6条店：寺岡、BIPROGY）、TGN（2店舗：寺岡、BIPROGY）、福太郎（2店舗：寺岡、BIPROGY） 株ツルハでは「寺岡精工」の棚札に決定 ・北海道中心 ・食品売場オンリー設置87店舗、全売場設置2店舗 | H22: CX推進部 店舗運営部 | I22: 齋藤 横井 | J22: 横井 | K22: 未着手 | M22: ・全ての販促が連携されているわけではない ・THD情報システムとの役割分担 棚札用集配信サーバー | N22: 寺岡へ現状確認 THD情シス確認 ツルハ現地確認（磯部さん、佑哉さん）
A23: =ROW()-1 -> 22 | B23: スマートデバイス | C23: 低 | D23: 低 | E23: スマートデバイス | F23: ・店舗オペレーションの効率化（売り場即時対応） 品出し・棚割確認、在庫確認、値引き・期限チェック ・接客サービス向上 商品検索、在庫確認（他店舗含む） ・本部指示の迅速な展開 売場変更指示、販促指示、緊急連絡、店舗写真報告 ・教育・ナレッジ共有 チャットボット、接客動画、業務マニュアル | H23: CX推進部 店舗運営部 | I23: 石川 足立 | K23: 未着手 | N23: イオンリテール ウエルシア→コンタクト中
A24: =ROW()-1 -> 23 | B24: 52週のMD | C24: 高 | D24: 低 | E24: 52週のMD | F24: 52週のMD可視化と送付、行動評価するためのデータベース作成 | H24: 店舗運営本部、 商品部、営業推進部 | I24: 横井 足立 | J24: 横井 | K24: 進行中 | M24: 横井：実施状況確認 毎週火曜日 まずはCX推進部で未実施タスク確認 ➡２週分の実績を共有 RPA関連事項の確認 | N24: 全店稼働１週目 現在実施中 重点20カテゴリー選定
A25: =ROW()-1 -> 24 | B25: 日中清算店舗の月末日締めでミス多発 | C25: 高 | D25: 高 | E25: 日中清算 | F25: 日中清算でも末日は夜締め | H25: 全店 | I25: 横井 | J25: 横井 | K25: 進行中 | M25: 店舗クラウドにて月末の日中清算ができないように改修することは可能か？ | N25: THD状況確認
A26: =ROW()-1 -> 25 | B26: 生鮮EDIリリース後の課題 | C26: 中 | D26: 低 | E26: 生鮮EDI | F26: ・「せんどねっと」での棚卸実施、差益管理 ・青果粗利向上 | H26: 商品部 | I26: 齋藤 | J26: 齋藤 | K26: 進行中 | M26: ・導入リスト作成時間増 ・粗利率0.3%→案検討できていない（1%目標は数値根拠なし）→商品部対応 | N26: ・店舗作業低減時間の確認 ・差益管理（棚卸機能）の運用 ・常温センター対応（ロジスティード）
A27: =ROW()-1 -> 26 | B27: 棚卸精度向上のための運用見直し | C27: 高 | D27: 低 | E27: 棚卸 | F27: ・ロスチェック精度向上 ・業者棚卸の精度向上 | H27: 経理 情報システム CX推進部 | I27: 鈴木佑 齋藤 横井 | K27: 停止 | M27: 運用体制、役割分担整理 →情報システムが各店舗のロス修正入力チェックをしている →修正件数が多い、修正漏れが多いため根本的な対策 | N27: 次回棚卸準備時に体制検討
A28: =ROW()-1 -> 27 | B28: AIカメラ 遠隔 | C28: 低 | D28: 低 | E28: サードアイズ社 Safie | F28: 生鮮、ベーカリー部門の売り場監視、評価をAIが行い、売り場の標準化、マネージャー業務の効率化を目指す 【導入実績】成城石井、スーパーサンエイ、フードウェイ | H28: 店舗企画部 運営支援課 CX推進部 情報システム部 | I28: 横井 石川 | J28: 横井 | K28: 未着手 | M28: 運営支援課 ﾍﾞｰｶﾘｰﾄﾚｰﾅｰ、生鮮ﾄﾚｰﾅｰの課題把握 Safie vs サードアイズ | N28: 3/24 サードアイズ説明 運営支援課参加予定 4/14or4/20 Safie
A29: =ROW()-1 -> 28 | B29: 予算対比実績の即時化、精度向上、効率化 | C29: 低 | D29: 低 | E29: 予算実績集計 DIGGLE ログラス | F29: ・集計の即時化 ・TK5からのEXCEL出力→マクロ集計からの解放 ・減価償却実績の自動集計 | H29: 経営企画部 | I29: 鈴木佑 齋藤 | J29: 齋藤 | K29: 未着手 | M29: コストの問題 DIGGLE: IC150万、RC30万 ログラス:IC150万、RC50万 内製を検討 | N29: AIエージェントで対応可能か検討
A30: =ROW()-1 -> 29 | B30: IT-BCP | C30: 高 | D30: 低 | E30: ガートナー エスピーネットワーク | F30: IT関連、ランサムウェアを加味した事業継続計画を作成 緊急連絡網の効率化 １．原因ではなく「結果事象」にフォーカスする ２．想定すべき７つの結果事象（リスク） ①システム機器の機能不能②施設・設備の不能③人員の移動制限④ITリソースの共有停止⑤人的ソースの供給停止⑥長期間のシステム隔離・安全⑦データの大規模な破壊 ３．影響度分析（BIA）のアップデート ４．コンテンジェンシープランの見直し ５．暫定復旧の考え方 | H30: 総務部 情報システム部 CX推進部 | I30: 鈴木佑 齋藤 | J30: 齋藤 | K30: 調査中 | M30: 検討課題整理 BCPとBCP規定 BCP：行動手順書 BCP規定：組織・ルール | N30: エスピーネットワークへ提案依頼中
A31: =ROW()-1 -> 30 | B31: AI使用ガイドライン作成 | C31: 高 | D31: 中 | E31: AI使用ガイドライン | F31: AI使用に関するルール整理 | H31: CX推進部 | I31: 鈴木孝 石川 | J31: 石川 | K31: 進行中 | M31: Claud GWS | N31: 運用乗せるための規定作成 ガートナーとの壁打ち
A32: =ROW()-1 -> 31 | B32: 店長チェックリスト | C32: 低 | D32: 低 | E32: 【コンプライアス】店長チェックリスト | F32: 内部監査業務の細分化 ①毎日実施業務・・・毎日確認する項目 ②週間実施業務・・・一週間の中で確認する業務 ③月初実施業務・・・月の初めに確認・実施する業務 ④月末実施業務・・・月末に確認・実施する業務 ⑤年間・発生都度実施業務・・・年間の中で定期的に発生、または不定期に発生する業務 | H32: 店舗企画部 業務改善課 | I32: 鈴木孝 横井 | J32: 鈴木孝 | K32: 未着手 | M32: 監査書類 ポイント付与実績
A33: =ROW()-1 -> 32 | B33: RFID | C33: 中 | D33: 中 | H33: CX推進部 店舗運営部 | I33: 鈴木佑 横井 | J33: 横井 | K33: 着手 | N33: 3/17：小橋本部長MTG 担当：佑哉、横井、支社長
A34: =ROW()-1 -> 33 | B34: AI-OCR | C34: 低 | D34: 低 | E34: 蒼AOI CODIQ PKSHA | F34: JAPAN AIのOCR アンケートの読み取りする→VOC 売価調整（チラシを見てEXCEL入力）→経営インパクト大 作成時のチラシチェック→１～３項 チラシ作成機能は検討可能か？ | H34: CX推進部 営業推進部 | I34: 鈴木孝 足立 | J34: 鈴木孝 | K34: 調査中 | L34: 5月12日マーケティング部含め再打合わせセッティング、課題明確化 | M34: チラシ読み取りデモ→精度は少し良くないが改善の余地あり 営業推進部ではBPOも検討 | N34: ・3/17：会社紹介 ・営業推進部へ提案
A35: =ROW()-1 -> 34 | B35: 販促企画CCR登録用リスト作成、登録、チェックの効率化 | C35: 低 | D35: 低 | E35: 旧販促企画システム（デジコム） | H35: 営業推進部 | I35: 横井 足立 | J35: 横井 | K35: 未着手
A36: =ROW()-1 -> 35 | B36: レイアウト集約 | C36: 中 | D36: 中 | E36: 棚割（プロモ、エンド） | F36: 個店ごとのプロモーション棚割りを数パターンに集約する | H36: 商品部 CX推進部 | I36: 足立 石川 | K36: 未着手 | N36: プロモと売上の相関関係より最適パターンを割り出しする
A37: =ROW()-1 -> 36 | B37: 改鮮活動 | C37: 高 | D37: 低 | E37: ロート製薬 | F37: 第1優先：気づき活動 ※まずはここの定着を1年かけて作りたい（気づき、発言・提案する文化） 第2優先：5Sの見える化 第3優先：テーマ活動 ★活動は「やること」よりも、風化させない運営機能 | H37: 全部署 | I37: 横井 | J37: 横井 | K37: 未着手 | M37: 初回で決めたいこと 目的を統一する 「現場を楽にする」「問題を見える化する」「改善できる人を育てる」 活動名称とメッセージを決める 事務局設置 モデル拠点選定 投稿フォーマット、会議体、KPI決定 | N37: 4/15：キックオフ 4/24：ロート様打ち合わせ
A38: =ROW()-1 -> 37 | B38: 従業員アンケート、インタビュー | C38: 高 | D38: 高 | E38: ぼぼまる（博報堂） | F38: 従業員のエンゲージメントを高める | H38: 全部署 | K38: 未着手
A39: =ROW()-1 -> 38 | B39: POP作成エージェント | C39: 中 | D39: 中 | E39: 業務フロー | F39: ラベルマイティ販売停止による代替検討 | H39: 店舗運営部 商品部 | K39: 未着手
A40: =ROW()-1 -> 39 | B40: 業務可視化 | C40: 高 | D40: 低 | E40: 業務フロー | F40: バリューチェーン清流化 業務可視化、ボトルネック特定 業務のシンプル化、働きやすさ向上、顧客価値向上 GTMエンジニア | H40: 全部署 | I40: 横井 鈴木孝 | J40: 鈴木孝 横井 | K40: 調査中 | L40: 4/17 Cacoo打合せ予定 | M40: 業務フロー作成ツール | N40: 4/3：SIGNATE AI総合コンサル
...

Sheet CX進捗0330
A1: # | B1: 課題 （現状と影響） | C1: 重要 度 | D1: 緊急 度 | E1: PJキーワード | F1: PJ内容 （施策の要点） | G1: 期間・期限 （マイルストーン） | H1: 関係部門 | I1: CX担当 | J1: 当週 進捗記入 | K1: ステータス | L1: 進捗 「計画に対してどこまで進んでいるか」 | M1: 課題・リスク 「問題は何か、将来の危険は何か」 | N1: 対応方針・アクション 「どう解決するか、次に何をやるか」 | O1: 意思決定事項 「経営・上位者に判断してほしいこと」 | P1: KPI・成果 「どれだけ価値が出ているか」
A2: =ROW()-1 -> 1 | B2: 欠品低減に向けての取り組み | C2: 高 | D2: 中 | E2: 信頼の棚 自動発注 | F2: ・入替リスト実施精度向上 ・最低在庫１→２ ・欠品調査PG、現状把握・分析・対応 バイヤー軸、店舗運営部軸 | G2: ・2/1全店欠品調査 開始 ・3/1商品部、店舗運営部用分析画面リリース ・欠品チェックメンションRPA | H2: CX推進部 商品部 店舗運営部 | I2: 齋藤 足立 | J2: 齋藤 | K2: 進行中 | L2: 全店タイムスケジュールに落とし込み実施 | M2: 調査漏れがある 欠品数が減っていない 欠品数が少ないと思われる店舗がある | N2: ・詳細を坪井泰樹さんからヒアリング 3/31_欠品対策運用の徹底 ・3月末 欠品チェックリマインドRPA作成 経営戦略本部：現地確認
A3: =ROW()-1 -> 2 | B3: グループウェア導入 | C3: 高 | D3: 高 | E3: グループウェア | F3: デスクネッツネオ、サイバーメールの導入 | G3: ・サイバーメイル運用開始：物販4/6（月）、調剤4/4（土） ・杏林堂MSドメイン終了：2027.02.28 | H3: 全社 | I3: 横井 足立 | J3: 横井 | K3: 進行中 | L3: ■3月27日週進捗 ・名刺依頼集計してデザインG作成依頼済 ・Cybermail用のグループアドレスの部署確認完了 ・店舗の事前準備指示済み ■今週対応 ・Outlookで継続配信されるものの一覧 ・個人アドレスではない部署の切替タスク確認 ■残課題 ・メールフォルダ５０GB拡張の遅れ ・名刺作成がCybermail稼働後 ・開業支援の掲示物変更確認 | M3: ①名刺の差し替え→6万枚\63,360 ・HD所属を除く：298,320円（税抜）＝約30万 ・HD所属を含む：397,440円（税抜）＝約40万 ★原稿作成２W、印刷２営業日 ②役員以上の方のCybermailの周知 ③メールフォルダ容量の拡張の必要性 ・50G拡張：毎月約25万円 ④4/1移動者のアドレス申請→間に合いません ⑤outlookメール終了 店舗：2026/07終了 本部員：2027/02/28終了 ⑥outlookスケジュール連携 ⑦事故報告書：THDよりデスクネッツネオを利用に運用変更 ・添付容量確認 社長グループの選定 事故報告書メンションの設定 メールアカウント管理→情報システム | N3: 事前準備 outlookのグループアドレス帳整備 →情報システム部へ依頼 新ネットフォルダの展開 →本部員各自でインストール依頼予定 メールフォルダの準備 アカウント申請整理
A4: =ROW()-1 -> 3 | B4: 商品部、店舗運営部 業務可視化、生産性向上 | C4: 高 | D4: 高 | E4: Qasee分析 | F4: PCの操作ログ（アプリ使用時間、キー入力量など）を自動収集アプリを導入 | H4: 商品部 店舗運営部 | I4: 鈴木孝 | J4: 鈴木孝 | K4: 進行中 | L4: 4/16に商品部にて状況振り返りがあるため、そこで課題を確認し今後の展開を検討予定 | M4: 自動で振り分けられない作業を「仕分け」する必要があるが、やり切れていない。 運用初期なので、運用が上手く乗るまで少し細かくチェック。 | N4: 商品部の業務分析 ・鈴木雅彦・小峰・疋田・大庭・栗田・中野
A5: =ROW()-1 -> 4 | B5: 契約書レビューAIクラウド | C5: 中 | D5: 低 | E5: リセ LeCHECK | F5: 契約書レビューAIクラウドの導入検討 ・レビューの効率化 ・契約リスクの早期発見 トラブル防止、コンプライアンス強化 ・法務ナレッジの標準化 担当者依存から脱却 すすかけリーガルチェック 2026年3月まで 21件、2025年 80件、2024年 131件、2023年 105件 すずかけ顧問料：月2.7万円 | G5: ・3/19導入済 ・4月末まで：法務リサーチ機能β版追加 | H5: 総務 | I5: 鈴木孝 齋藤 | J5: 齋藤 | K5: 進行中 | L5: 3/19導入済 契約3ID（赤星さん、中村桂さん、鈴木恵美さん） 特別オファー 99,000円/月 チェック件数、DLひな形 年間無制限 | M5: 開発部、お客様相談室にて把握できていないリーガルチェックあり 新しい法律（取適法）などに対しても弁護士30人でチェック | N5: リセ社より操作説明予定（予定調整中） 法務リサーチ機能β版追加、総務に機能リリースのつなぎまでCXで行う
A6: =ROW()-1 -> 5 | B6: 議事録自動化AIエージェント導入 | C6: 高 | D6: 高 | E6: JAPAN AI | F6: 生成AI活用 ・２か月試験運用で継続判断 ・AIエージェント内製開発も視野 | H6: CX推進部 | I6: 横井 鈴木孝 足立 | J6: 鈴木孝 | K6: 進行中 | L6: トライアル待ち | M6: リーガルチェックにて漏れ発生 ・プロバイダー側が勝手に利用規約変更、サービス終了 ・損害賠償責任の上限がない | N6: 3/23 JAPAN AI契約
A7: =ROW()-1 -> 6 | B7: 資料作成AIエージェント導入 | C7: 高 | D7: 高 | E7: JAPAN AI | F7: 生成AI活用 | H7: CX推進部 | I7: 横井 鈴木孝 足立 | J7: 鈴木孝 | K7: 進行中 | L7: NotebookLM（GWS導入）に進捗あり 足立：4月中に5社と面談し情報収集 | M7: JAPAN AI導入 NotebookLM（GWS導入） | N7: 3/23 JAPAN AI契約
A8: =ROW()-1 -> 7 | B8: 価格ロジックと販促見直し | C8: 高 | D8: 中 | E8: 単品売価上下影響 価格弾力性 | F8: 値付け適正化と会社影響、販促重複の把握 割引率による弾力性調査 | H8: 営業推進部 CX推進部 | I8: 石川 | K8: 進行中 | M8: DB構築とAIエージェント活用の検討 | N8: CODIQ分析、方向性検討 3/18
A9: =ROW()-1 -> 8 | B9: ツルハAIチャットボット導入 | C9: 中 | D9: 中 | E9: Knowledge Forest TeachMeBiz廃止 RAG MCP | F9: THD、NECで作成したAIチャットボット 杏林堂には改修可能な開発スペース マニュアル精査等はTHD業務改革Gが指導 Claude Codeライセンス追加 | G9: ・ツルハ：2026年5月リリース予定 ・杏林堂：2026年9月リリース目標 | H9: CX推進部 店舗運営部 THD経営企画部 | I9: 足立 鈴木孝 | K9: 進行中 | L9: 足立：マニュアル管理方法を確立・ヘルプドックを試用し使用感の確認 | M9: チャットボット応答精度、対応範囲決め 調剤部適応、労務smartHRとのすみわけ TeachMeBiz廃止→マニュアル格納場所検討 マニュアル/QA対応しやすいAIエージェントの模索（VINX） | N9: マニュアル精査 標準的なチャットボットのアーキテクト確認 JAPAN AIとの比較
A10: =ROW()-1 -> 9 | B10: 店舗出店予測の向上 | C10: 高 | D10: 低 | E10: 店舗出店予測 SalesSencer | F10: ウエルシアTruedata社SalesSencerの導入 IC約3000万円、RC約3500万円 AIエージェント作成（CODIQ） | H10: 店舗開発本部 経営戦略本部 | I10: 石川 足立 | K10: 未着手 | M10: 予測精度向上5%まで （現状：25%～40%、SalesSencer：10%） | N10: ツルハHD取締役会決議事項（ツルハHD開発本部長 遠山取締役 上申予定） CODIQにて過去データより別途活用方法検討
A11: =ROW()-1 -> 10 | B11: 勤務割、ワークフロー | C11: 中 | D11: 中 | E11: ワークフロー | F11: EXCELマクロによる ・ワークフロー作成の効率化 ×R-Shift | H11: 物販 調剤 ネットスーパー | I11: 横井 鈴木孝 | K11: 進行中 | M11: ・ワークスケジュールAIエージェントまたはアプリの導入 ・感情加味したシフト作成 調剤：調整機能必要 | N11: ・CODIQ相談中 ・ワークフローアプリ調査中
A12: =ROW()-1 -> 11 | B12: 店舗応援依頼作業の最適化、省人化 | C12: 中 | D12: 中 | E12: 応援マッチング | F12: EXCELマクロによる ・店舗応援の効率化 | H12: 物販 調剤 ネットスーパー | I12: 横井 鈴木孝 | J12: 鈴木孝 | K12: 進行中 | L12: マクロ調整中 | M12: ・応援計算ツール EXCELマクロ調剤調整中 →調剤：15日までシフト作成、16日ツール使用の運用 →物販：運用可能か確認中 | N12: ・応援マッチング マクロ改修、運用調整 ・CODIQ相談中
A13: =ROW()-1 -> 12 | B13: 経理月次締め処理の清流化 | C13: 高 | D13: 高 | E13: 経理締め処理 | F13: 属人化作業を廃止して清流化する 2026年5月まで | H13: 経理 情報システム CX推進部 | I13: 石川 | J13: 石川 | K13: 進行中 | L13: 高山さんにヒアリングしたところ経理に引継ぎ中とのこと。 経理で引き継げない内容があればこちらに連絡いただけるそうなので現在待ち状態 | M13: ・属人化業務（高山さんPG）の共通化 | N13: ・経理Martsolution業務落とし込み ・高山さんPG対応
A14: =ROW()-1 -> 13 | B14: 店舗連絡のルールメイキング | C14: 高 | D14: 高 | E14: 連絡ルール統一PJ | F14: メール件名のルール作成 わかりやすい件名にして店舗連絡精度を向上 | H14: 全社 | I14: 横井 鈴木孝 | J14: 横井 | K14: 進行中 | L14: ルールの仮案は整理済み Cybermailのテンプレート機能を使用 | M14: mailto環境依存度の確認 労務：「通達」と「辞令（社報）」 | N14: ・各部意見集約 4/14：打ち合わせ
A15: =ROW()-1 -> 14 | B15: AI棚割導入 | C15: 中 | D15: 低 | E15: Tanagram Sotoremaneger プリファードNW | F15: エンド、プロモの棚割り（全店約1万本）作成 ストマネAIの検討 写真から棚割り作成（店舗入替後の入力軽減） | H15: 商品部 | I15: 横井 | J15: 横井 | K15: 未着手 | M15: 作成精度 運用方法（都度CSVファイルを手動で取込しなければならない） | N15: ・花王AI棚割り確認 →川島さんへ ・プリファードNWの紹介 →商品部、店舗運営部
A16: =ROW()-1 -> 15 | B16: KOGORO改修 | C16: 高 | D16: 高 | E16: KOGORO | F16: ・商品部、営業推進部のレポートを帳票にする ・日次予算作成ロジック改修 ・カテゴリー変更後実績反映ロジック ・正味売上粗利 | H16: CX推進部 商品部 店舗運営部 経営企画部 | I16: 石川 | K16: 進行中 | M16: 神戸DCへのサーバー移行スケジュール未確定（発注から3か月） 開発サーバー容量不足 D:200G残/800G 外付けSSD追加（2t） | N16: 次回要件定義 3月下旬帳票レイアウト改修一部リリース 日別予算ロジック設計 ETL設計3月末まで→開発 ジョブスケジューリング
A17: =ROW()-1 -> 16 | B17: コロンボ、かみさんの更新改修 | C17: 中 | D17: 中 | E17: コロンボ | F17: ・かみさんの更新改修 | H17: CX推進部 | I17: 石川 | K17: 着手 | M17: KOGOROと重複 かみさんの利用シーンを整理 | N17: 仕様確認中
A18: =ROW()-1 -> 17 | B18: 内製アプリ | C18: 中 | D18: 中 | E18: 買取DC 欠品調査PG | F18: アプリ使用のDB管理（MySQL） | H18: CX推進部 | I18: 足立 石川 | K18: 未着手 | M18: 神戸DCへのサーバー移行：RedHatがない
A19: =ROW()-1 -> 18 | B19: VoC収集 | C19: 高 | D19: 中 | E19: お客様の声 | F19: VoC収集→分類→改善のサイクル設計、顧客体験指標の運用 まじかまじボイス ・クレーム ・商品要望 ・本社宛クレーム→THD報告 イオングループ：SalesForece 博報堂 アソボーノ 生成AI活用サービス | H19: CX推進部 業務推進部 お客様相談室 | I19: 鈴木孝 石川 齋藤 鈴木佑 | J19: 石川 | K19: 進行中 | L19: 増田支社長にご連絡して以下店舗でQRコードによるアンケートを試験運用予定。 ・根洗店 ・新初生店 https://forms.office.com/r/YHpAwN80Bd 店舗、場所単位でQRを定義 | M19: お客様の声 ・お客様相談室 HP ・ポイント管理事務局 ・店舗紙→AIーOCR ・QRコード アンケートフォーム ・掲示方法 店舗の返信内容の改善（お客様相談室） ・商品仕入れの依頼時に他の商品をお勧めしない ・過去の返信内容がわからない→Gemini活用 履歴管理が不徹底 | N19: 静岡支社で検証 キックオフ調整中 お客様の声の返信フロー
A20: =ROW()-1 -> 19 | B20: RPA統合、スリム化して対応範囲を広げる | C20: 高 | D20: 高 | E20: RPA | F20: ・営業推進タスク精査 ・日次生産性Power BI ・労務RPA コスト：169,400円／月 | H20: 全社 | I20: 足立 石川 | K20: 進行中 | L20: 足立：石川さんへ不足データの共有（済） | M20: 個人向けタスクの精査
A21: =ROW()-1 -> 20 | B21: コミュニケーション基盤 | C21: 中 | D21: 中 | E21: MSライセンス | F21: 1. 組織の情報共有のリアルタイム化（属人化を防ぎ、組織の情報資産を可視化） 2. 部門・拠点を超えたコラボレーション促進（サイロ化結合、スピードを向上） 3. 業務プロセスのデジタル化（業務プロセスデジタル化、生産性を向上） 4. ナレッジマネジメントの実現（組織知の蓄積） 5. DX施策の展開プラットフォーム（DXを拡張する基盤、社内チャットボット） 6. 働き方改革・リモートワーク対応（柔軟な働き方と人材確保） | G21: MSリセラー変更タイミング ・杏林堂ドメイン終了：2027/02/28 ・ツルハドメイン開始：2027/03/01 | H21: 全社 | I21: 鈴木孝 横井 | J21: 鈴木孝 横井 | K21: 未着手 | L21: 未着手 M365のスケジュール連携は ツルハドメイン開始後なら可能 杏林堂のライセンスでは不可 ≪追記≫ 検証はHDで進める想定とのこと HD情報システム部杉山さん➡鳥居さんへ進言しているとのこと | M21: 固有のアドレスは別メールサーバーで立ち上げ可能か検討 | N21: 杏林堂コスト算出（MSから見積提出）
A22: =ROW()-1 -> 21 | B22: 電子棚札導入 | C22: 高 | D22: 低 | E22: 電子棚札 | F22: 株ツルハ（本郷店、北6条店：寺岡、BIPROGY）、TGN（2店舗：寺岡、BIPROGY）、福太郎（2店舗：寺岡、BIPROGY） 株ツルハでは「寺岡精工」の棚札に決定 ・北海道中心 ・食品売場オンリー設置87店舗、全売場設置2店舗 | H22: CX推進部 店舗運営部 | I22: 齋藤 横井 | J22: 横井 | K22: 未着手 | L22: 未着手 HDの動向を聞きつつ、進行待ち | M22: ・全ての販促が連携されているわけではない ・THD情報システムとの役割分担 棚札用集配信サーバー | N22: 寺岡へ現状確認 THD情シス確認 ツルハ現地確認（磯部さん、佑哉さん）
A23: =ROW()-1 -> 22 | B23: スマートデバイス | C23: 低 | D23: 低 | E23: スマートデバイス | F23: ・店舗オペレーションの効率化（売り場即時対応） 品出し・棚割確認、在庫確認、値引き・期限チェック ・接客サービス向上 商品検索、在庫確認（他店舗含む） ・本部指示の迅速な展開 売場変更指示、販促指示、緊急連絡、店舗写真報告 ・教育・ナレッジ共有 チャットボット、接客動画、業務マニュアル | H23: CX推進部 店舗運営部 | I23: 石川 足立 | K23: 未着手 | N23: イオンリテール ウエルシア→コンタクト中
A24: =ROW()-1 -> 23 | B24: 52週のMD | C24: 高 | D24: 低 | E24: 52週のMD | F24: 52週のMD可視化と送付、行動評価するためのデータベース作成 | H24: 店舗運営本部、 商品部、営業推進部 | I24: 横井 足立 | J24: 横井 | K24: 進行中 | L24: 実施率の配信後の支社長の動き 1週目のタスクチェックに比べて 実行率は上がっているが、2週前のタスクで支社長チェックの漏れが一部あり | M24: 横井：実施状況確認 毎週火曜日 まずはCX推進部で未実施タスク確認 ➡２週分の実績を共有 RPA関連事項の確認 | N24: 全店稼働１週目 現在実施中 重点20カテゴリー選定
A25: =ROW()-1 -> 24 | B25: 日中清算店舗の月末日締めでミス多発 | C25: 高 | D25: 高 | E25: 日中清算 | F25: 日中清算でも末日は夜締め | H25: 全店 | I25: 横井 | J25: 横井 | K25: 進行中 | L25: 日中精算の展開は進めている状態 方針はシステム改修をなしで一旦様子見 | M25: 店舗クラウドにて月末の日中清算ができないように改修することは可能か？ | N25: THD状況確認
A26: =ROW()-1 -> 25 | B26: 生鮮EDIリリース後の課題 | C26: 中 | D26: 低 | E26: 生鮮EDI | F26: ・「せんどねっと」での棚卸実施、差益管理 ・青果粗利向上 | H26: 商品部 | I26: 齋藤 | J26: 齋藤 | K26: 進行中 | M26: ・導入リスト作成時間増 ・粗利率0.3%→案検討できていない（1%目標は数値根拠なし）→商品部対応 | N26: ・店舗作業低減時間の確認 ・差益管理（棚卸機能）の運用 ・常温センター対応（ロジスティード）
A27: =ROW()-1 -> 26 | B27: 棚卸精度向上のための運用見直し | C27: 高 | D27: 低 | E27: 棚卸 | F27: ・ロスチェック精度向上 ・業者棚卸の精度向上 | H27: 経理 情報システム CX推進部 | I27: 鈴木佑 齋藤 横井 | K27: 停止 | M27: 運用体制、役割分担整理 →情報システムが各店舗のロス修正入力チェックをしている →修正件数が多い、修正漏れが多いため根本的な対策 | N27: 次回棚卸準備時に体制検討
A28: =ROW()-1 -> 27 | B28: AIカメラ 遠隔 | C28: 低 | D28: 低 | E28: サードアイズ社 Safie | F28: 生鮮、ベーカリー部門の売り場監視、評価をAIが行い、売り場の標準化、マネージャー業務の効率化を目指す 【導入実績】成城石井、スーパーサンエイ、フードウェイ | H28: 店舗企画部 運営支援課 CX推進部 情報システム部 | I28: 横井 石川 | J28: 横井 | K28: 未着手 | L28: 次回説明会まで一旦進捗なし | M28: 運営支援課 ﾍﾞｰｶﾘｰﾄﾚｰﾅｰ、生鮮ﾄﾚｰﾅｰの課題把握 Safie vs サードアイズ | N28: 3/24 サードアイズ説明 運営支援課参加予定 4/14or4/20 Safie
A29: =ROW()-1 -> 28 | B29: 予算対比実績の即時化、精度向上、効率化 | C29: 低 | D29: 低 | E29: 予算実績集計 DIGGLE ログラス | F29: ・集計の即時化 ・TK5からのEXCEL出力→マクロ集計からの解放 ・減価償却実績の自動集計 | H29: 経営企画部 | I29: 鈴木佑 齋藤 | J29: 齋藤 | K29: 未着手 | L29: 経営企画部への紹介 →ランニングコストで断念 | M29: コストの問題 DIGGLE: IC150万、RC30万 ログラス:IC150万、RC50万 内製を検討 | N29: AIエージェントで対応可能か検討
A30: =ROW()-1 -> 29 | B30: IT-BCP | C30: 高 | D30: 低 | E30: ガートナー エスピーネットワーク | F30: IT関連、ランサムウェアを加味した事業継続計画を作成 緊急連絡網の効率化 １．原因ではなく「結果事象」にフォーカスする ２．想定すべき７つの結果事象（リスク） ①システム機器の機能不能②施設・設備の不能③人員の移動制限④ITリソースの共有停止⑤人的ソースの供給停止⑥長期間のシステム隔離・安全⑦データの大規模な破壊 ３．影響度分析（BIA）のアップデート ４．コンテンジェンシープランの見直し ５．暫定復旧の考え方 | H30: 総務部 情報システム部 CX推進部 | I30: 鈴木佑 齋藤 | J30: 齋藤 | K30: 調査中 | L30: 3/30 事前会議 | M30: 検討課題整理 BCPとBCP規定 BCP：行動手順書 BCP規定：組織・ルール | N30: エスピーネットワークへ提案依頼中
A31: =ROW()-1 -> 30 | B31: AI使用ガイドライン作成 | C31: 高 | D31: 中 | E31: AI使用ガイドライン | F31: AI使用に関するルール整理 | H31: CX推進部 | I31: 鈴木孝 石川 | J31: 石川 | K31: 進行中 | L31: ガイドライン案は作成済み。 | M31: Claud GWS | N31: 運用乗せるための規定作成 ガートナーとの壁打ち
A32: =ROW()-1 -> 31 | B32: 店長チェックリスト | C32: 低 | D32: 低 | E32: 【コンプライアス】店長チェックリスト | F32: 内部監査業務の細分化 ①毎日実施業務・・・毎日確認する項目 ②週間実施業務・・・一週間の中で確認する業務 ③月初実施業務・・・月の初めに確認・実施する業務 ④月末実施業務・・・月末に確認・実施する業務 ⑤年間・発生都度実施業務・・・年間の中で定期的に発生、または不定期に発生する業務 | H32: 店舗企画部 業務改善課 | I32: 鈴木孝 横井 | J32: 鈴木孝 | K32: 未着手 | L32: 未着手 | M32: 監査書類 ポイント付与実績
A33: =ROW()-1 -> 32 | B33: RFID | C33: 中 | D33: 中 | H33: CX推進部 店舗運営部 | I33: 鈴木佑 横井 | J33: 横井 | K33: 着手 | L33: 4月3日（金）初回MTで体制図の確認 以降週1回の定期MT | N33: 3/17：小橋本部長MTG 担当：佑哉、横井、支社長
A34: =ROW()-1 -> 33 | B34: AI-OCR | C34: 低 | D34: 低 | E34: 蒼AOI CODIQ PKSHA | F34: JAPAN AIのOCR アンケートの読み取りする→VOC 売価調整（チラシを見てEXCEL入力）→経営インパクト大 作成時のチラシチェック→１～３項 チラシ作成機能は検討可能か？ | H34: CX推進部 営業推進部 | I34: 鈴木孝 足立 | J34: 鈴木孝 | K34: 未着手 | L34: マーケティング部の業務大幅削減の可能性 池田さんに商談参加依頼済 | M34: チラシ読み取りデモ→精度は少し良くないが改善の余地あり 営業推進部ではBPOも検討 | N34: ・3/17：会社紹介 ・営業推進部へ提案
A35: =ROW()-1 -> 34 | B35: 販促企画CCR登録用リスト作成、登録、チェックの効率化 | C35: 低 | D35: 低 | E35: 旧販促企画システム（デジコム） | H35: 営業推進部 | I35: 横井 足立 | J35: 横井 | K35: 未着手 | L35: 未着手
A36: =ROW()-1 -> 35 | B36: レイアウト集約 | C36: 中 | D36: 中 | E36: 棚割（プロモ、エンド） | F36: 個店ごとのプロモーション棚割りを数パターンに集約する | H36: 商品部 CX推進部 | I36: 足立 石川 | K36: 未着手 | N36: プロモと売上の相関関係より最適パターンを割り出しする
A37: =ROW()-1 -> 36 | B37: 改鮮活動 | C37: 高 | D37: 低 | E37: ロート製薬 | F37: 第1優先：気づき活動 ※まずはここの定着を1年かけて作りたい（気づき、発言・提案する文化） 第2優先：5Sの見える化 第3優先：テーマ活動 ★活動は「やること」よりも、風化させない運営機能 | H37: 全部署 | I37: 横井 | J37: 横井 | K37: 未着手 | L37: キックオフミーティングまで未着手 | M37: 初回で決めたいこと 目的を統一する 「現場を楽にする」「問題を見える化する」「改善できる人を育てる」 活動名称とメッセージを決める 事務局設置 モデル拠点選定 投稿フォーマット、会議体、KPI決定 | N37: 4/15：キックオフ 4/24：ロート様打ち合わせ
A38: =ROW()-1 -> 37 | B38: 従業員アンケート、インタビュー | C38: 高 | D38: 高 | E38: ぼぼまる（博報堂） | F38: 従業員のエンゲージメントを高める | H38: 全部署 | K38: 未着手
A39: =ROW()-1 -> 38 | B39: POP作成エージェント | C39: 中 | D39: 中 | E39: 業務フロー | F39: ラベルマイティ販売停止による代替検討 | H39: 店舗運営部 商品部 | K39: 未着手
A40: =ROW()-1 -> 39 | B40: 業務可視化 | C40: 高 | D40: 低 | E40: 業務フロー | F40: バリューチェーン清流化 業務可視化、ボトルネック特定 業務のシンプル化、働きやすさ向上、顧客価値向上 GTMエンジニア | H40: 全部署 | I40: 横井 鈴木孝 | J40: 鈴木孝 横井 | K40: 未着手 | L40: WindowsVisio：追加費用なく作成可能、作りやすいか正直微妙 cacoo：月額550円、ブラウザで使用可能 4月17日説明会参加 | M40: 業務フロー作成ツール | N40: 4/3：SIGNATE AI総合コンサル
...

Sheet CX進捗0323
A1: # | B1: 課題 （現状と影響） | C1: 重要 度 | D1: 緊急 度 | E1: PJキーワード | F1: PJ内容 （施策の要点） | G1: 期間・期限 （マイルストーン） | H1: 関係部門 | I1: CX担当 | J1: 当週 進捗記入 | K1: ステータス | L1: 進捗 「計画に対してどこまで進んでいるか」 | M1: 課題・リスク 「問題は何か、将来の危険は何か」 | N1: 対応方針・アクション 「どう解決するか、次に何をやるか」 | O1: 意思決定事項 「経営・上位者に判断してほしいこと」 | P1: KPI・成果 「どれだけ価値が出ているか」
A2: =ROW()-1 -> 1 | B2: 欠品低減に向けての取り組み | C2: 高 | D2: 中 | E2: 信頼の棚 自動発注 | F2: ・入替リスト実施精度向上 ・最低在庫１→２ ・欠品調査PG、現状把握・分析・対応 バイヤー軸、店舗運営部軸 | G2: ・2/1全店欠品調査 開始 ・3/1商品部、店舗運営部用分析画面リリース ・欠品チェックメンションRPA | H2: CX推進部 商品部 店舗運営部 | I2: 齋藤 足立 | J2: 齋藤 | K2: 進行中 | L2: 全店タイムスケジュールに落とし込み実施 | M2: 調査漏れがある 欠品数が減っていない 欠品数が少ないと思われる店舗がある | N2: 欠品対策運用の徹底 ・3月末 欠品チェックリマインドRPA作成 経営戦略本部：現地確認
A3: =ROW()-1 -> 2 | B3: グループウェア導入 | C3: 高 | D3: 高 | E3: グループウェア | F3: デスクネッツネオ、サイバーメールの導入 | G3: ・サイバーメイル運用開始：物販4/6（月）、調剤4/4（土） ・杏林堂MSドメイン終了：2027.02.28 | H3: 全社 | I3: 横井 足立 | K3: 進行中 | M3: ①名刺の差し替え→6万枚\63,360 ・HD所属を除く：298,320円（税抜）＝約30万 ・HD所属を含む：397,440円（税抜）＝約40万 ★原稿作成２W、印刷２営業日 ②役員以上の方のCybermailの周知 ③メールフォルダ容量の拡張の必要性 ・50G拡張：毎月約25万円 ④4/1移動者のアドレス申請→間に合いません ⑤outlookメール終了 店舗：2026/07終了 本部員：2027/02/28終了 ⑥outlookスケジュール連携 ⑦事故報告書：THDよりデスクネッツネオを利用に運用変更 ・添付容量確認 社長グループの選定 事故報告書メンションの設定 メールアカウント管理→情報システム | N3: 事前準備 outlookのグループアドレス帳整備 →情報システム部へ依頼 新ネットフォルダの展開 →本部員各自でインストール依頼予定 メールフォルダの準備 アカウント申請整理 | O3: ■Outlook➡Cybermailに移行させるグループについて Cybermailでは部署のアドレスを指定した場合に Outlookのように分解して小河路社長を除くことができません。 よって小河路社長が含まれるべき Cybermailのグループを確認してほしい
A4: =ROW()-1 -> 3 | B4: 商品部、店舗運営部 業務可視化、生産性向上 | C4: 高 | D4: 高 | E4: Qasee分析 | F4: PCの操作ログ（アプリ使用時間、キー入力量など）を自動収集アプリを導入 | H4: 商品部 店舗運営部 | I4: 鈴木孝 | J4: 鈴木孝 | K4: 進行中 | L4: 4/16に商品部にて状況振り返りがあるため、そこで課題を確認し今後の展開を検討予定 | M4: 自動で振り分けられない作業を「仕分け」する必要があるが、やり切れていない。 運用初期なので、運用が上手く乗るまで少し細かくチェック。 | N4: 商品部の業務分析 ・鈴木雅彦・小峰・疋田・大庭・栗田・中野
A5: =ROW()-1 -> 4 | B5: 契約書レビューAIクラウド | C5: 中 | D5: 低 | E5: リセ LeCHECK | F5: 契約書レビューAIクラウドの導入検討 ・レビューの効率化 ・契約リスクの早期発見 トラブル防止、コンプライアンス強化 ・法務ナレッジの標準化 担当者依存から脱却 すすかけリーガルチェック 2026年3月まで 21件、2025年 80件、2024年 131件、2023年 105件 すずかけ顧問料：月2.7万円 | G5: ・3/19導入済 ・4月末まで：法務リサーチ機能β版追加 | H5: 総務 | I5: 鈴木孝 齋藤 | J5: 齋藤 | K5: 進行中 | L5: 3/19導入済 契約3ID（赤星さん、中村桂さん、鈴木恵美さん） 特別オファー 99,000円/月 チェック件数、DLひな形 年間無制限 | M5: 開発部、お客様相談室にて把握できていないリーガルチェックあり 新しい法律（取適法）などに対しても弁護士30人でチェック | N5: リセ社より操作説明予定（予定調整中） 法務リサーチ機能β版追加、総務に機能リリースのつなぎまでCXで行う
A6: =ROW()-1 -> 5 | B6: 議事録自動化AIエージェント導入 | C6: 高 | D6: 高 | E6: JAPAN AI | F6: 生成AI活用 ・２か月試験運用で継続判断 ・AIエージェント内製開発も視野 | H6: CX推進部 | I6: 横井 鈴木孝 足立 | J6: 鈴木孝 | K6: 進行中 | L6: トライアル待ち | M6: リーガルチェックにて漏れ発生 ・プロバイダー側が勝手に利用規約変更、サービス終了 ・損害賠償責任の上限がない | N6: 3/23 JAPAN AI契約
A7: =ROW()-1 -> 6 | B7: 資料作成AIエージェント導入 | C7: 高 | D7: 高 | E7: JAPAN AI | F7: 生成AI活用 | H7: CX推進部 | I7: 横井 鈴木孝 足立 | J7: 鈴木孝 | K7: 進行中 | L7: NotebookLM（GWS導入）に進捗あり | M7: JAPAN AI導入 NotebookLM（GWS導入） | N7: 3/23 JAPAN AI契約
A8: =ROW()-1 -> 7 | B8: 価格ロジックと販促見直し | C8: 高 | D8: 中 | E8: 単品売価上下影響 価格弾力性 | F8: 値付け適正化と会社影響、販促重複の把握 割引率による弾力性調査 | H8: 営業推進部 CX推進部 | I8: 石川 | K8: 進行中 | M8: DB構築とAIエージェント活用の検討 | N8: CODIQ分析、方向性検討 3/18
A9: =ROW()-1 -> 8 | B9: ツルハAIチャットボット導入 | C9: 中 | D9: 中 | E9: Knowledge Forest TeachMeBiz廃止 RAG MCP | F9: THD、NECで作成したAIチャットボット 杏林堂には改修可能な開発スペース マニュアル精査等はTHD業務改革Gが指導 Claude Codeライセンス追加 | G9: ・ツルハ：2026年5月リリース予定 ・杏林堂：2026年9月リリース目標 | H9: CX推進部 店舗運営部 THD経営企画部 | I9: 足立 鈴木孝 | K9: 進行中 | M9: チャットボット応答精度、対応範囲決め 調剤部適応、労務smartHRとのすみわけ TeachMeBiz廃止→マニュアル格納場所検討 マニュアル/QA対応しやすいAIエージェントの模索（VINX） | N9: マニュアル精査 標準的なチャットボットのアーキテクト確認 JAPAN AIとの比較
A10: =ROW()-1 -> 9 | B10: 店舗出店予測の向上 | C10: 高 | D10: 低 | E10: 店舗出店予測 SalesSencer | F10: ウエルシアTruedata社SalesSencerの導入 IC約3000万円、RC約3500万円 AIエージェント作成（CODIQ） | H10: 店舗開発本部 経営戦略本部 | I10: 石川 足立 | K10: 未着手 | M10: 予測精度向上5%まで （現状：25%～40%、SalesSencer：10%） | N10: ツルハHD取締役会決議事項（ツルハHD開発本部長 遠山取締役 上申予定） CODIQにて過去データより別途活用方法検討
A11: =ROW()-1 -> 10 | B11: 勤務割、ワークフロー | C11: 中 | D11: 中 | E11: ワークフロー | F11: EXCELマクロによる ・ワークフロー作成の効率化 ×R-Shift | H11: 物販 調剤 ネットスーパー | I11: 横井 鈴木孝 | K11: 進行中 | M11: ・ワークスケジュールAIエージェントまたはアプリの導入 ・感情加味したシフト作成 調剤：調整機能必要 | N11: ・CODIQ相談中 ・ワークフローアプリ調査中
A12: =ROW()-1 -> 11 | B12: 店舗応援依頼作業の最適化、省人化 | C12: 中 | D12: 中 | E12: 応援マッチング | F12: EXCELマクロによる ・店舗応援の効率化 | H12: 物販 調剤 ネットスーパー | I12: 横井 鈴木孝 | J12: 鈴木孝 | K12: 進行中 | L12: マクロ調整中 | M12: ・応援計算ツール EXCELマクロ調剤調整中 →調剤：15日までシフト作成、16日ツール使用の運用 →物販：運用可能か確認中 | N12: ・応援マッチング マクロ改修、運用調整 ・CODIQ相談中
A13: =ROW()-1 -> 12 | B13: 経理月次締め処理の清流化 | C13: 高 | D13: 高 | E13: 経理締め処理 | F13: 属人化作業を廃止して清流化する 2026年5月まで | H13: 経理 情報システム CX推進部 | I13: 石川 | J13: 石川 | K13: 進行中 | L13: 高山さんにヒアリングしたところ経理に引継ぎ中とのこと。 経理で引き継げない内容があればこちらに連絡いただけるそうなので現在待ち状態 | M13: ・属人化業務（高山さんPG）の共通化 | N13: ・経理Martsolution業務落とし込み ・高山さんPG対応
A14: =ROW()-1 -> 13 | B14: 店舗連絡のルールメイキング | C14: 高 | D14: 高 | E14: 連絡ルール統一PJ | F14: メール件名のルール作成 わかりやすい件名にして店舗連絡精度を向上 | H14: 全社 | I14: 横井 鈴木孝 | K14: 進行中 | M14: mailto環境依存度の確認 労務：「通達」と「辞令（社報）」 | N14: ・各部意見集約 4/14：打ち合わせ
A15: =ROW()-1 -> 14 | B15: AI棚割導入 | C15: 中 | D15: 低 | E15: Tanagram Sotoremaneger プリファードNW | F15: エンド、プロモの棚割り（全店約1万本）作成 ストマネAIの検討 写真から棚割り作成（店舗入替後の入力軽減） | H15: 商品部 | I15: 横井 | K15: 進行中 | M15: 作成精度 運用方法（都度CSVファイルを手動で取込しなければならない） | N15: ・花王AI棚割り確認 →川島さんへ ・プリファードNWの紹介 →商品部、店舗運営部
A16: =ROW()-1 -> 15 | B16: KOGORO改修 | C16: 高 | D16: 高 | E16: KOGORO | F16: ・商品部、営業推進部のレポートを帳票にする ・日次予算作成ロジック改修 ・カテゴリー変更後実績反映ロジック ・正味売上粗利 | H16: CX推進部 商品部 店舗運営部 経営企画部 | I16: 石川 | K16: 進行中 | M16: 神戸DCへのサーバー移行スケジュール未確定（発注から3か月） 開発サーバー容量不足 D:200G残/800G 外付けSSD追加（2t） | N16: 次回要件定義 3月下旬帳票レイアウト改修一部リリース 日別予算ロジック設計 ETL設計3月末まで→開発 ジョブスケジューリング
A17: =ROW()-1 -> 16 | B17: コロンボ、かみさんの更新改修 | C17: 中 | D17: 中 | E17: コロンボ | F17: ・かみさんの更新改修 | H17: CX推進部 | I17: 石川 | K17: 着手 | M17: KOGOROと重複 かみさんの利用シーンを整理 | N17: 仕様確認中
A18: =ROW()-1 -> 17 | B18: 内製アプリ | C18: 中 | D18: 中 | E18: 買取DC 欠品調査PG | F18: アプリ使用のDB管理（MySQL） | H18: CX推進部 | I18: 足立 石川 | K18: 未着手 | M18: 神戸DCへのサーバー移行：RedHatがない
A19: =ROW()-1 -> 18 | B19: VoC収集 | C19: 高 | D19: 中 | E19: お客様の声 | F19: VoC収集→分類→改善のサイクル設計、顧客体験指標の運用 まじかまじボイス ・クレーム ・商品要望 ・本社宛クレーム→THD報告 イオングループ：SalesForece 博報堂 アソボーノ 生成AI活用サービス | H19: CX推進部 業務推進部 お客様相談室 | I19: 鈴木孝 石川 | J19: 石川 | K19: 進行中 | L19: 増田支社長にご連絡して以下店舗でQRコードによるアンケートを試験運用予定。 ・根洗店 ・新初生店 https://forms.office.com/r/YHpAwN80Bd 店舗、場所単位でQRを定義 | M19: お客様の声 ・お客様相談室 HP ・ポイント管理事務局 ・店舗紙→AIーOCR ・QRコード アンケートフォーム ・掲示方法 店舗の返信内容の改善（お客様相談室） ・商品仕入れの依頼時に他の商品をお勧めしない ・過去の返信内容がわからない→Gemini活用 履歴管理が不徹底 | N19: お客様相談室の小田木さん、試験運用許可待ち
A20: =ROW()-1 -> 19 | B20: RPA統合、スリム化して対応範囲を広げる | C20: 高 | D20: 高 | E20: RPA | F20: ・営業推進タスク精査 ・日次生産性Power BI ・労務RPA コスト：169,400円／月 | H20: 全社 | I20: 足立 石川 | K20: 進行中
A21: =ROW()-1 -> 20 | B21: コミュニケーション基盤 | C21: 中 | D21: 中 | E21: MSライセンス | F21: 1. 組織の情報共有のリアルタイム化（属人化を防ぎ、組織の情報資産を可視化） 2. 部門・拠点を超えたコラボレーション促進（サイロ化結合、スピードを向上） 3. 業務プロセスのデジタル化（業務プロセスデジタル化、生産性を向上） 4. ナレッジマネジメントの実現（組織知の蓄積） 5. DX施策の展開プラットフォーム（DXを拡張する基盤、社内チャットボット） 6. 働き方改革・リモートワーク対応（柔軟な働き方と人材確保） | G21: MSリセラー変更タイミング ・杏林堂ドメイン終了：2027/02/28 ・ツルハドメイン開始：2027/03/01 | H21: 全社 | I21: 鈴木孝 横井 | J21: 鈴木孝 | K21: 未着手 | L21: 未着手 M365のスケジュール連携は ツルハドメイン開始後なら可能 杏林堂のライセンスでは不可 | M21: 固有のアドレスは別メールサーバーで立ち上げ可能か検討 | N21: 杏林堂コスト算出（MSから見積提出）
A22: =ROW()-1 -> 21 | B22: 電子棚札導入 | C22: 高 | D22: 低 | E22: 電子棚札 | F22: 株ツルハ（本郷店、北6条店：寺岡、BIPROGY）、TGN（2店舗：寺岡、BIPROGY）、福太郎（2店舗：寺岡、BIPROGY） 株ツルハでは「寺岡精工」の棚札に決定 ・北海道中心 ・食品売場オンリー設置87店舗、全売場設置2店舗 | H22: CX推進部 店舗運営部 | I22: 齋藤 横井 | K22: 未着手 | M22: ・全ての販促が連携されているわけではない ・THD情報システムとの役割分担 棚札用集配信サーバー | N22: 寺岡へ現状確認 THD情シス確認 ツルハ現地確認（磯部さん、佑哉さん）
A23: =ROW()-1 -> 22 | B23: スマートデバイス | C23: 低 | D23: 低 | E23: スマートデバイス | F23: ・店舗オペレーションの効率化（売り場即時対応） 品出し・棚割確認、在庫確認、値引き・期限チェック ・接客サービス向上 商品検索、在庫確認（他店舗含む） ・本部指示の迅速な展開 売場変更指示、販促指示、緊急連絡、店舗写真報告 ・教育・ナレッジ共有 チャットボット、接客動画、業務マニュアル | H23: CX推進部 店舗運営部 | I23: 石川 足立 | K23: 未着手 | N23: イオンリテール ウエルシア
A24: =ROW()-1 -> 23 | B24: 52週のMD | C24: 高 | D24: 低 | E24: 52週のMD | F24: 52週のMD可視化と送付、行動評価するためのデータベース作成 | H24: 店舗運営本部、 商品部、営業推進部 | I24: 横井 足立 | K24: 進行中 | M24: 横井：実施状況確認 毎週火曜日 まずはCX推進部で未実施タスク確認 ➡２週分の実績を共有 RPA関連事項の確認 | N24: 全店稼働１週目 現在実施中 重点20カテゴリー選定
A25: =ROW()-1 -> 24 | B25: 日中清算店舗の月末日締めでミス多発 | C25: 高 | D25: 高 | E25: 日中清算 | F25: 日中清算でも末日は夜締め | H25: 全店 | I25: 横井 | K25: 停止 | M25: 店舗クラウドにて月末の日中清算ができないように改修することは可能か？ | N25: THD状況確認
A26: =ROW()-1 -> 25 | B26: 生鮮EDIリリース後の課題 | C26: 中 | D26: 低 | E26: 生鮮EDI | F26: ・「せんどねっと」での棚卸実施、差益管理 ・青果粗利向上 | H26: 商品部 | I26: 齋藤 | J26: 齋藤 | K26: 進行中 | M26: ・導入リスト作成時間増 ・粗利率0.3%→案検討できていない（1%目標は数値根拠なし）→商品部対応 | N26: ・店舗作業低減時間の確認 ・差益管理（棚卸機能）の運用 ・常温センター対応（ロジスティード）
A27: =ROW()-1 -> 26 | B27: 棚卸精度向上のための運用見直し | C27: 高 | D27: 低 | E27: 棚卸 | F27: ・ロスチェック精度向上 ・業者棚卸の精度向上 | H27: 経理 情報システム CX推進部 | I27: 鈴木佑 齋藤 横井 | K27: 停止 | M27: 運用体制、役割分担整理 →情報システムが各店舗のロス修正入力チェックをしている →修正件数が多い、修正漏れが多いため根本的な対策 | N27: 次回棚卸準備時に体制検討
A28: =ROW()-1 -> 27 | B28: AIカメラ 遠隔 | C28: 低 | D28: 低 | E28: サードアイズ社 Safie | F28: 生鮮、ベーカリー部門の売り場監視、評価をAIが行い、売り場の標準化、マネージャー業務の効率化を目指す 【導入実績】成城石井、スーパーサンエイ、フードウェイ | H28: 店舗企画部 運営支援課 CX推進部 情報システム部 | I28: 横井 石川 | K28: 未着手 | M28: 運営支援課 ﾍﾞｰｶﾘｰﾄﾚｰﾅｰ、生鮮ﾄﾚｰﾅｰの課題把握 Safie vs サードアイズ | N28: 3/24 サードアイズ説明 運営支援課参加予定 4/14or4/20 Safie
A29: =ROW()-1 -> 28 | B29: 予算対比実績の即時化、精度向上、効率化 | C29: 低 | D29: 低 | E29: 予算実績集計 DIGGLE ログラス | F29: ・集計の即時化 ・TK5からのEXCEL出力→マクロ集計からの解放 ・減価償却実績の自動集計 | H29: 経営企画部 | I29: 鈴木佑 齋藤 | J29: 齋藤 | K29: 未着手 | M29: コストの問題 DIGGLE: IC150万、RC30万 ログラス:IC150万、RC50万 内製を検討 | N29: 経営企画部への紹介 →ランニングコストで断念
A30: =ROW()-1 -> 29 | B30: IT-BCP | C30: 高 | D30: 低 | E30: ガートナー エスピーネットワーク | F30: IT関連、ランサムウェアを加味した事業継続計画を作成 緊急連絡網の効率化 １．原因ではなく「結果事象」にフォーカスする ２．想定すべき７つの結果事象（リスク） ①システム機器の機能不能②施設・設備の不能③人員の移動制限④ITリソースの共有停止⑤人的ソースの供給停止⑥長期間のシステム隔離・安全⑦データの大規模な破壊 ３．影響度分析（BIA）のアップデート ４．コンテンジェンシープランの見直し ５．暫定復旧の考え方 | H30: 総務部 情報システム部 CX推進部 | I30: 鈴木佑 齋藤 | J30: 齋藤 | K30: 調査中 | M30: 検討課題整理 BCPとBCP規定 BCP：行動手順書 BCP規定：組織・ルール | N30: 3/9 ガートナーインクワイアリ 4/1 エスピーネットワーク 3/30 事前会議
A31: =ROW()-1 -> 30 | B31: AI使用ガイドライン作成 | C31: 高 | D31: 中 | E31: AI使用ガイドライン | F31: AI使用に関するルール整理 | H31: CX推進部 | I31: 鈴木孝 石川 | J31: 石川 | K31: 進行中 | L31: ガイドライン案は作成済み。 | M31: Claud GWS | N31: 運用乗せるための規定作成 ガートナーとの壁打ち
A32: =ROW()-1 -> 31 | B32: 店長チェックリスト | C32: 低 | D32: 低 | E32: 【コンプライアス】店長チェックリスト | F32: 内部監査業務の細分化 ①毎日実施業務・・・毎日確認する項目 ②週間実施業務・・・一週間の中で確認する業務 ③月初実施業務・・・月の初めに確認・実施する業務 ④月末実施業務・・・月末に確認・実施する業務 ⑤年間・発生都度実施業務・・・年間の中で定期的に発生、または不定期に発生する業務 | H32: 店舗企画部 業務改善課 | I32: 鈴木孝 横井 | J32: 鈴木孝 | K32: 未着手 | L32: 未着手 | M32: 監査書類 ポイント付与実績
A33: =ROW()-1 -> 32 | B33: RFID | C33: 中 | D33: 中 | H33: CX推進部 店舗運営部 | I33: 鈴木佑 横井 | K33: 未着手 | N33: 3/17：小橋本部長MTG 担当：佑哉、横井、支社長
A34: =ROW()-1 -> 33 | B34: AI-OCR | C34: 低 | D34: 低 | E34: 蒼AOI CODIQ PKSHA | F34: JAPAN AIのOCR アンケートの読み取りする→VOC 売価調整（チラシを見てEXCEL入力）→経営インパクト大 作成時のチラシチェック→１～３項 チラシ作成機能は検討可能か？ | H34: CX推進部 営業推進部 | I34: 鈴木孝 足立 | J34: 鈴木孝 | K34: 未着手 | L34: マーケティング部の業務大幅削減の可能性 池田さんに商談参加依頼済 | M34: チラシ読み取りデモ→精度は少し良くないが改善の余地あり 営業推進部ではBPOも検討 | N34: ・3/17：会社紹介 ・営業推進部へ提案
A35: =ROW()-1 -> 34 | B35: 販促企画CCR登録用リスト作成、登録、チェックの効率化 | C35: 低 | D35: 低 | E35: 旧販促企画システム（デジコム） | H35: 営業推進部 | I35: 横井 足立 | K35: 未着手
A36: =ROW()-1 -> 35 | B36: レイアウト集約 | C36: 中 | D36: 中 | E36: 棚割（プロモ、エンド） | F36: 個店ごとのプロモーション棚割りを数パターンに集約する | H36: 商品部 CX推進部 | I36: 足立 石川 | K36: 未着手 | N36: プロモと売上の相関関係より最適パターンを割り出しする
A37: =ROW()-1 -> 36 | B37: 改鮮活動 | C37: 高 | D37: 低 | E37: ロート製薬 | F37: 第1優先：気づき活動 ※まずはここの定着を1年かけて作りたい（気づき、発言・提案する文化） 第2優先：5Sの見える化 第3優先：テーマ活動 ★活動は「やること」よりも、風化させない運営機能 | H37: 全部署 | I37: 横井 | K37: 未着手 | M37: 初回で決めたいこと 目的を統一する 「現場を楽にする」「問題を見える化する」「改善できる人を育てる」 活動名称とメッセージを決める 事務局設置 モデル拠点選定 投稿フォーマット、会議体、KPI決定 | N37: 4/15：キックオフ 4/24：ロート様打ち合わせ
A38: =ROW()-1 -> 37 | B38: 従業員アンケート、インタビュー | C38: 高 | D38: 高 | E38: ぼぼまる（博報堂） | F38: 従業員のエンゲージメントを高める | H38: 全部署 | K38: 未着手
A39: =ROW()-1 -> 38 | B39: 業務可視化 | C39: 高 | D39: 低 | E39: 業務フロー | F39: バリューチェーン清流化 業務可視化、ボトルネック特定 業務のシンプル化、働きやすさ向上、顧客価値向上 GTMエンジニア | H39: 全部署 | I39: 横井 鈴木孝 | J39: 鈴木孝 | K39: 未着手 | L39: WindowsVisio：追加費用なく作成可能、作りやすいか正直微妙 cacoo：月額550円、ブラウザで使用可能 | M39: 業務フロー作成ツール | N39: 4/3：SIGNATE AI総合コンサル
A40: =ROW()-1 -> 39 | B40: AIエージェント開発環境構築 | C40: 高 | D40: 高 | F40: ◆ニューワークフローの構築（業務の再設計） ◆５レイヤー １．人とAIが共に働くシステム（Any workspace） ２．AIエージェントを開発・管理するシステム（Any agent） ３．安全性とガバナンスを担保するレイヤー（Trust layer） ４．AIがビジネスを理解するデータ文脈システム（Data Cloud等のデータレイク・ウェアハウス） ５．業務プロセスを担うシステム（各種業務アプリケーション） | H40: CX推進部 | K40: 未着手 | M40: 業務フロー作成ツール AIによるパフォーマンスが落ちる場合がある ワークスロップ（Workslop） →業務の熟練者とAIが組み合わさるとパフォーマンスが上がる
...

Sheet CX進捗0316
A1: # | B1: 課題 （現状と影響） | C1: 重要 度 | D1: 緊急 度 | E1: PJキーワード | F1: PJ内容 （施策の要点） | G1: 期間・期限 （マイルストーン） | H1: 関係部門 | I1: CX担当 | J1: 当週 進捗記入 | K1: ステータス | L1: 進捗 「計画に対してどこまで進んでいるか」 | M1: 課題・リスク 「問題は何か、将来の危険は何か」 | N1: 対応方針・アクション 「どう解決するか、次に何をやるか」 | O1: 意思決定事項 「経営・上位者に判断してほしいこと」 | P1: KPI・成果 「どれだけ価値が出ているか」
A2: 1 | B2: 欠品低減に向けての取り組み | C2: 高 | D2: 中 | E2: 信頼の棚 自動発注 | F2: ・入替リスト実施精度向上 ・最低在庫１→２ ・欠品調査PG、現状把握・分析・対応 バイヤー軸、店舗運営部軸 | G2: ・2/1全店欠品調査 開始 ・3/1商品部、店舗運営部用分析画面リリース ・欠品チェックメンションRPA | H2: CX推進部 商品部 店舗運営部 | I2: 齋藤 足立 | J2: 齋藤 | K2: 進行中 | M2: 欠品対策の浸透が現場まで落ち切れていない 欠品が正確に把握できていない 3/11 ・欠品登録されていない ・欠品対策ができていない 欠品調査がワークスケジュールに落ちていない | N2: 3/10 支社長MTGにて運用方法検討 3/11 MTG実施 ・タイスケ落とし込み 3/18 欠品集計機能追加（店舗運営部、商品部） 3月末 欠品チェックリマインドRPA作成
A3: 2 | B3: グループウェア導入 | C3: 高 | D3: 高 | E3: グループウェア | F3: デスクネッツネオ、サイバーメールの導入 | G3: ・サイバーメイル運用開始：物販4/6（月）、調剤4/4（土） ・杏林堂MSドメイン終了：2027.02.28 | H3: 全社 | I3: 横井 足立 | K3: 進行中 | M3: ①名刺の差し替え→6万枚\63,360 ・HD所属を除く：298,320円（税抜）＝約30万 ・HD所属を含む：397,440円（税抜）＝約40万 ★原稿作成２W、印刷２営業日 ②役員以上の方のCybermailの周知 ③メールフォルダ容量の拡張の必要性 ・50G拡張：毎月約25万円 ④4/1移動者のアドレス申請→間に合いません ⑤outlookメール終了 店舗：2026/07終了 本部員：2027/02/28終了 ⑥outlookスケジュール連携 ⑦事故報告書：THDよりデスクネッツネオを利用に運用変更 ・添付容量確認 社長グループの選定 事故報告書メンションの設定 メールアカウント管理→情報システム | N3: 事前準備 outlookのグループアドレス帳整備 →情報システム部へ依頼 新ネットフォルダの展開 →本部員各自でインストール依頼予定 メールフォルダの準備 アカウント申請整理
A4: 3 | B4: 商品部、店舗運営部 業務可視化、生産性向上 | C4: 高 | D4: 高 | E4: Qasee分析 | F4: PCの操作ログ（アプリ使用時間、キー入力量など）を自動収集アプリを導入 | H4: 商品部 店舗運営部 | I4: 鈴木孝 | K4: 進行中 | M4: 自動で振り分けられない作業を「仕分け」する必要があるが、やり切れていない。 運用初期なので、運用が上手く乗るまで少し細かくチェック。 | N4: 商品部の業務分析 ・鈴木雅彦・小峰・疋田・大庭・栗田・中野
A5: 4 | B5: 契約書レビューAIクラウド | C5: 中 | D5: 低 | E5: リセ LeCHECK | F5: 契約書レビューAIクラウドの導入検討 ・レビューの効率化 ・契約リスクの早期発見 トラブル防止、コンプライアンス強化 ・法務ナレッジの標準化 担当者依存から脱却 すすかけリーガルチェック 2026年3月まで 21件、2025年 80件、2024年 131件、2023年 105件 すずかけ顧問料：月2.7万円 | G5: ・3/19導入済 ・4月末まで：法務リサーチ機能β版追加 | H5: 総務 | I5: 鈴木孝 齋藤 | J5: 齋藤 | K5: 進行中 | L5: 3/19導入済 契約3ID（赤星さん、中村桂さん、鈴木恵美さん） 特別オファー 99,000円/月 チェック件数、DLひな形 年間無制限 | M5: 開発部、お客様相談室にて把握できていないリーガルチェックあり 新しい法律（取適法）などに対しても弁護士30人でチェック | N5: リセ社より操作説明予定（予定調整中） 法務リサーチ機能β版追加、総務に機能リリースのつなぎまでCXで行う
A6: 5 | B6: 議事録自動化AIエージェント導入 | C6: 高 | D6: 高 | E6: JAPAN AI | F6: 生成AI活用 ・２か月試験運用で継続判断 ・AIエージェント内製開発も視野 | H6: CX推進部 | I6: 横井 鈴木孝 足立 | K6: 進行中 | M6: リーガルチェックにて漏れ発生 ・プロバイダー側が勝手に利用規約変更、サービス終了 ・損害賠償責任の上限がない | N6: 3/23 JAPAN AI契約
A7: 6 | B7: 資料作成AIエージェント導入 | C7: 高 | D7: 高 | E7: JAPAN AI | F7: 生成AI活用 | H7: CX推進部 | I7: 横井 鈴木孝 足立 | K7: 進行中 | M7: JAPAN AI導入 NotebookLM（GWS導入） | N7: 3/23 JAPAN AI契約
A8: 7 | B8: 価格ロジックと販促見直し | C8: 高 | D8: 中 | E8: 単品売価上下影響 価格弾力性 | F8: 値付け適正化と会社影響、販促重複の把握 割引率による弾力性調査 | H8: 営業推進部 CX推進部 | I8: 石川 | K8: 進行中 | M8: DB構築とAIエージェント活用の検討 | N8: CODIQ分析、方向性検討 3/18
A9: 8 | B9: ツルハAIチャットボット導入 | C9: 中 | D9: 中 | E9: Knowledge Forest TeachMeBiz廃止 RAG MCP | F9: THD、NECで作成したAIチャットボット 杏林堂には改修可能な開発スペース マニュアル精査等はTHD業務改革Gが指導 Claude Codeライセンス追加 | G9: ・ツルハ：2026年5月リリース予定 ・杏林堂：2026年9月リリース目標 | H9: CX推進部 店舗運営部 THD経営企画部 | I9: 足立 鈴木孝 | K9: 進行中 | M9: チャットボット応答精度、対応範囲決め 調剤部適応、労務smartHRとのすみわけ TeachMeBiz廃止→マニュアル格納場所検討 マニュアル/QA対応しやすいAIエージェントの模索（VINX） | N9: マニュアル精査 標準的なチャットボットのアーキテクト確認 JAPAN AIとの比較
A10: 9 | B10: 店舗出店予測の向上 | C10: 高 | D10: 低 | E10: 店舗出店予測 SalesSencer | F10: ウエルシアTruedata社SalesSencerの導入 IC約3000万円、RC約3500万円 AIエージェント作成（CODIQ） | H10: 店舗開発本部 経営戦略本部 | I10: 齋藤 石川 | J10: 齋藤 | K10: 未着手 | M10: 予測精度向上5%まで （現状：25%～40%、SalesSencer：10%） | N10: ツルハHD取締役会決議事項（ツルハHD開発本部長 遠山取締役 上申予定） CODIQにて過去データより別途活用方法検討
A11: 10 | B11: 勤務割、ワークフロー | C11: 中 | D11: 中 | E11: ワークフロー | F11: EXCELマクロによる ・ワークフロー作成の効率化 ×R-Shift | H11: 物販 調剤 ネットスーパー | I11: 横井 鈴木孝 | K11: 進行中 | M11: ・ワークスケジュールAIエージェントまたはアプリの導入 ・感情加味したシフト作成 調剤：調整機能必要 | N11: ・CODIQ相談中 ・ワークフローアプリ調査中
A12: 11 | B12: 店舗応援依頼作業の最適化、省人化 | C12: 中 | D12: 中 | E12: 応援マッチング | F12: EXCELマクロによる ・店舗応援の効率化 | H12: 物販 調剤 ネットスーパー | I12: 横井 鈴木孝 | K12: 進行中 | M12: ・応援計算ツール EXCELマクロ調剤調整中 →調剤：15日までシフト作成、16日ツール使用の運用 →物販：運用可能か確認中 | N12: ・応援マッチング マクロ改修、運用調整 ・CODIQ相談中
A13: 12 | B13: 経理月次締め処理の清流化 | C13: 高 | D13: 高 | E13: 経理締め処理 | F13: 属人化作業を廃止して清流化する 2026年5月まで | H13: 経理 情報システム CX推進部 | I13: 石川 | J13: 石川 | K13: 進行中 | L13: 高山さんにヒアリングしたところ経理に引継ぎ中とのこと。 経理で引き継げない内容があればこちらに連絡いただけるそうなので現在待ち状態 | M13: ・属人化業務（高山さんPG）の共通化 | N13: ・経理Martsolution業務落とし込み ・高山さんPG対応
A14: 13 | B14: 店舗連絡のルールメイキング | C14: 高 | D14: 高 | E14: 連絡ルール統一PJ | F14: メール件名のルール作成 わかりやすい件名にして店舗連絡精度を向上 | H14: 全社 | I14: 横井 鈴木孝 | K14: 進行中 | M14: mailto環境依存度の確認 労務：「通達」と「辞令（社報）」 | N14: ・各部意見集約 4/14：打ち合わせ
A15: 14 | B15: AI棚割導入 | C15: 中 | D15: 低 | E15: Tanagram Sotoremaneger プリファードNW | F15: エンド、プロモの棚割り（全店約1万本）作成 ストマネAIの検討 写真から棚割り作成（店舗入替後の入力軽減） | H15: 商品部 | I15: 横井 | K15: 進行中 | M15: 作成精度 運用方法（都度CSVファイルを手動で取込しなければならない） | N15: ・花王AI棚割り確認 →川島さんへ ・プリファードNWの紹介 →商品部、店舗運営部
A16: 15 | B16: KOGORO改修 | C16: 高 | D16: 高 | E16: KOGORO | F16: ・商品部、営業推進部のレポートを帳票にする ・日次予算作成ロジック改修 ・カテゴリー変更後実績反映ロジック ・正味売上粗利 | H16: CX推進部 商品部 店舗運営部 経営企画部 | I16: 石川 | K16: 進行中 | M16: 神戸DCへのサーバー移行スケジュール未確定（発注から3か月） 開発サーバー容量不足 D:200G残/800G 外付けSSD追加（2t） | N16: 次回要件定義 3月下旬帳票レイアウト改修一部リリース 日別予算ロジック設計 ETL設計3月末まで→開発 ジョブスケジューリング
A17: 16 | B17: コロンボ、かみさんの更新改修 | C17: 中 | D17: 中 | E17: コロンボ | F17: ・かみさんの更新改修 | H17: CX推進部 | I17: 石川 | K17: 着手 | M17: KOGOROと重複 かみさんの利用シーンを整理 | N17: 仕様確認中
A18: 17 | B18: 内製アプリ | C18: 中 | D18: 中 | E18: 買取DC 欠品調査PG | F18: アプリ使用のDB管理（MySQL） | H18: CX推進部 | I18: 足立 石川 | K18: 未着手 | M18: 神戸DCへのサーバー移行：RedHatがない
A19: 18 | B19: VoC収集 | C19: 高 | D19: 中 | E19: お客様の声 | F19: VoC収集→分類→改善のサイクル設計、顧客体験指標の運用 まじかまじボイス ・クレーム ・商品要望 ・本社宛クレーム→THD報告 | H19: CX推進部 | I19: 鈴木孝 石川 | J19: 石川 | K19: 進行中 | L19: 増田支社長にご連絡して以下店舗でQRコードによるアンケートを試験運用予定。 ・根洗店 ・新初生店 現在は増田支社長からお客様相談室の小田木さんへ内容確認依頼中。 | M19: お客様の声 ・お客様相談室 HP ・ポイント管理事務局 ・店舗紙→AIーOCR ・QRコード アンケートフォーム（MS） ・掲示方法 | N19: AOI PKSHA
A20: 19 | B20: RPA統合、スリム化して対応範囲を広げる | C20: 高 | D20: 高 | E20: RPA | F20: ・営業推進タスク精査 ・日次生産性Power BI ・労務RPA コスト：169,400円／月 | H20: 全社 | I20: 足立 石川 | K20: 進行中
A21: 20 | B21: コミュニケーション基盤 | C21: 中 | D21: 中 | E21: MSライセンス | F21: 1. 組織の情報共有のリアルタイム化（属人化を防ぎ、組織の情報資産を可視化） 2. 部門・拠点を超えたコラボレーション促進（サイロ化結合、スピードを向上） 3. 業務プロセスのデジタル化（業務プロセスデジタル化、生産性を向上） 4. ナレッジマネジメントの実現（組織知の蓄積） 5. DX施策の展開プラットフォーム（DXを拡張する基盤、社内チャットボット） 6. 働き方改革・リモートワーク対応（柔軟な働き方と人材確保） | G21: MSリセラー変更タイミング ・杏林堂ドメイン終了：2027/02/28 ・ツルハドメイン開始：2027/03/01 | H21: 全社 | I21: 鈴木孝 横井 | J21: 鈴木孝 | K21: 未着手 | L21: 未着手 | M21: 固有のアドレスは別メールサーバーで立ち上げ可能か検討 | N21: 杏林堂コスト算出（MSから見積提出）
A22: 21 | B22: 電子棚札導入 | C22: 高 | D22: 低 | E22: 電子棚札 | F22: 株ツルハ（本郷店、北6条店：寺岡、BIPROGY）、TGN（2店舗：寺岡、BIPROGY）、福太郎（2店舗：寺岡、BIPROGY） 株ツルハでは「寺岡精工」の棚札に決定 ・北海道中心 ・食品売場オンリー設置87店舗、全売場設置2店舗 | H22: CX推進部 店舗運営部 | I22: 齋藤 横井 | K22: 未着手 | M22: ・全ての販促が連携されているわけではない ・THD情報システムとの役割分担 棚札用集配信サーバー | N22: 寺岡へ現状確認 THD情シス確認 ツルハ現地確認（磯部さん、佑哉さん）
A23: 22 | B23: スマートデバイス | C23: 低 | D23: 低 | E23: スマートデバイス | F23: ・店舗オペレーションの効率化（売り場即時対応） 品出し・棚割確認、在庫確認、値引き・期限チェック ・接客サービス向上 商品検索、在庫確認（他店舗含む） ・本部指示の迅速な展開 売場変更指示、販促指示、緊急連絡、店舗写真報告 ・教育・ナレッジ共有 チャットボット、接客動画、業務マニュアル | H23: CX推進部 店舗運営部 | I23: 石川 足立 | K23: 未着手 | N23: イオンリテール ウエルシア
A24: 23 | B24: 52週のMD | C24: 高 | D24: 低 | E24: 52週のMD | F24: 52週のMD可視化と送付、行動評価するためのデータベース作成 | H24: 店舗運営本部、 商品部、営業推進部 | I24: 横井 足立 | K24: 進行中 | M24: 横井：実施状況確認 毎週火曜日 まずはCX推進部で未実施タスク確認 RPA関連事項の確認 | N24: 全店稼働１週目 現在実施中 重点20カテゴリー選定
A25: 24 | B25: 日中清算店舗の月末日締めでミス多発 | C25: 高 | D25: 高 | E25: 日中清算 | F25: 日中清算でも末日は夜締め | H25: 全店 | I25: 横井 | K25: 停止 | M25: 店舗クラウドにて月末の日中清算ができないように改修することは可能か？ | N25: THD状況確認
A26: 25 | B26: 生鮮EDIリリース後の課題 | C26: 中 | D26: 低 | E26: 生鮮EDI | F26: ・「せんどねっと」での棚卸実施、差益管理 ・青果粗利向上 | H26: 商品部 | I26: 齋藤 | J26: 齋藤 | K26: 進行中 | M26: ・導入リスト作成時間増 ・粗利率0.3%→案検討できていない（1%目標は数値根拠なし）→商品部対応 | N26: ・店舗作業低減時間の確認 ・差益管理（棚卸機能）の運用 ・常温センター対応（ロジスティード）
A27: 26 | B27: 棚卸精度向上のための運用見直し | C27: 高 | D27: 低 | E27: 棚卸 | F27: ・ロスチェック精度向上 ・業者棚卸の精度向上 | H27: 経理 情報システム CX推進部 | I27: 鈴木佑 齋藤 横井 | K27: 停止 | M27: 運用体制、役割分担整理 →情報システムが各店舗のロス修正入力チェックをしている →修正件数が多い、修正漏れが多いため根本的な対策 | N27: 次回棚卸準備時に体制検討
A28: 27 | B28: AIカメラ 遠隔 | C28: 低 | D28: 低 | E28: サードアイズ社 Safie | F28: 生鮮、ベーカリー部門の売り場監視、評価をAIが行い、売り場の標準化、マネージャー業務の効率化を目指す 【導入実績】成城石井、スーパーサンエイ、フードウェイ | H28: 店舗企画部 運営支援課 CX推進部 情報システム部 | I28: 横井 石川 | K28: 未着手 | M28: 運営支援課 ﾍﾞｰｶﾘｰﾄﾚｰﾅｰ、生鮮ﾄﾚｰﾅｰの課題把握 Safie vs サードアイズ | N28: 3/24 サードアイズ説明 運営支援課参加予定 4/14or4/20 Safie
A29: 28 | B29: 予算対比実績の即時化、精度向上、効率化 | C29: 低 | D29: 低 | E29: 予算実績集計 DIGGLE ログラス | F29: ・集計の即時化 ・TK5からのEXCEL出力→マクロ集計からの解放 ・減価償却実績の自動集計 | H29: 経営企画部 | I29: 鈴木佑 齋藤 | J29: 齋藤 | K29: 未着手 | M29: コストの問題 DIGGLE: IC150万、RC30万 ログラス:IC150万、RC50万 内製を検討 | N29: 経営企画部への紹介 →ランニングコストで断念
A30: 29 | B30: IT-BCP | C30: 高 | D30: 低 | E30: ガートナー エスピーネットワーク | F30: IT関連、ランサムウェアを加味した事業継続計画を作成 緊急連絡網の効率化 １．原因ではなく「結果事象」にフォーカスする ２．想定すべき７つの結果事象（リスク） ①システム機器の機能不能②施設・設備の不能③人員の移動制限④ITリソースの共有停止⑤人的ソースの供給停止⑥長期間のシステム隔離・安全⑦データの大規模な破壊 ３．影響度分析（BIA）のアップデート ４．コンテンジェンシープランの見直し ５．暫定復旧の考え方 | H30: 総務部 情報システム部 CX推進部 | I30: 鈴木佑 齋藤 | J30: 齋藤 | K30: 調査中 | M30: 検討課題整理 BCPとBCP規定 BCP：行動手順書 BCP規定：組織・ルール | N30: 3/9 ガートナーインクワイアリ 4/1 エスピーネットワーク 3/30 事前会議
A31: 30 | B31: AI使用ガイドライン作成 | C31: 高 | D31: 中 | E31: AI使用ガイドライン | F31: AI使用に関するルール整理 | H31: CX推進部 | I31: 鈴木孝 石川 | J31: 石川 | K31: 進行中 | L31: ガイドライン案は作成済み。 次ステップはガートナーとの壁打ち？ | M31: Claud GWS
A32: 31 | B32: 店長チェックリスト | C32: 低 | D32: 低 | E32: 【コンプライアス】店長チェックリスト | F32: 内部監査業務の細分化 ①毎日実施業務・・・毎日確認する項目 ②週間実施業務・・・一週間の中で確認する業務 ③月初実施業務・・・月の初めに確認・実施する業務 ④月末実施業務・・・月末に確認・実施する業務 ⑤年間・発生都度実施業務・・・年間の中で定期的に発生、または不定期に発生する業務 | H32: 店舗企画部 業務改善課 | I32: 鈴木孝 横井 | J32: 鈴木孝 | K32: 未着手 | L32: 未着手 | M32: 監査書類 ポイント付与実績
A33: 32 | B33: RFID | C33: 中 | D33: 中 | H33: CX推進部 店舗運営部 | I33: 鈴木佑 横井 | K33: 未着手 | N33: 3/17：小橋本部長MTG 担当：佑哉、横井、支社長
A34: 33 | B34: AI-OCR | C34: 低 | D34: 低 | E34: 蒼AOI CODIQ PKSHA | F34: JAPAN AIのOCR アンケートの読み取りする→VOC 売価調整（チラシを見てEXCEL入力）→経営インパクト大 作成時のチラシチェック→１～３項 チラシ作成機能は検討可能か？ | H34: CX推進部 営業推進部 | I34: 鈴木孝 足立 | J34: 鈴木孝 | K34: 未着手 | L34: マーケティング部の業務大幅削減の可能性 池田さんに商談参加依頼済 | M34: チラシ読み取りデモ→精度は少し良くないが改善の余地あり 営業推進部ではBPOも検討 | N34: ・3/17：会社紹介 ・営業推進部へ提案
A35: 34 | B35: 販促企画CCR登録用リスト作成、登録、チェックの効率化 | C35: 低 | D35: 低 | E35: 旧販促企画システム（デジコム） | H35: 営業推進部 | I35: 横井 足立 | K35: 未着手
A36: 35 | B36: レイアウト集約 | C36: 中 | D36: 中 | E36: 棚割（プロモ、エンド） | F36: 個店ごとのプロモーション棚割りを数パターンに集約する | H36: 商品部 CX推進部 | I36: 足立 石川 | K36: 未着手 | N36: プロモと売上の相関関係より最適パターンを割り出しする
A37: 36 | B37: 改鮮活動 | C37: 高 | D37: 低 | E37: ロート製薬 | F37: 第1優先：気づき活動 ※まずはここの定着を1年かけて作りたい（気づき、発言・提案する文化） 第2優先：5Sの見える化 第3優先：テーマ活動 ★活動は「やること」よりも、風化させない運営機能 | H37: 全部署 | I37: 横井 | K37: 未着手 | M37: 初回で決めたいこと 目的を統一する 「現場を楽にする」「問題を見える化する」「改善できる人を育てる」 活動名称とメッセージを決める 事務局設置 モデル拠点選定 投稿フォーマット、会議体、KPI決定 | N37: 4/15：キックオフ 4/24：ロート様打ち合わせ
A38: 37 | B38: 業務可視化 | C38: 高 | D38: 高 | E38: 業務フロー | F38: バリューチェーン清流化 業務可視化、ボトルネック特定 業務のシンプル化、働きやすさ向上、顧客価値向上 | H38: 全部署 | I38: 横井 鈴木孝 | J38: 鈴木孝 | K38: 未着手 | L38: WindowsVisio：追加費用なく作成可能、作りやすいか正直微妙 cacco：月額550円、ブラウザで使用可能 | M38: 業務フロー作成ツール | N38: 4/3：SIGNATE AI総合コンサル
A39: 他部署関連
A40: 39 | B40: 店舗業績診断 | C40: 中 | D40: 中 | E40: Dr.SUM MotionBorad | I40: - | J40: - | K40: 進行中
...
